Workbook
Name NativeTimeline_Order_Date: #N/A
Name Slicer_Delivery_Status: #N/A
Name Slicer_Payment_Method: #N/A
Name Slicer_Region: #N/A

Sheet PIVOT A
A1: Payment Method | B1: (All)
A3: Sum of Effective Sales | B3: Column Labels
A4: Row Labels | B4: Central | C4: East | D4: North | E4: South | F4: West | G4: Grand Total
A5: Books | B5: 0 | C5: 63 | D5: 64 | E5: 0 | F5: 0 | G5: 127
A6: Electronics | B6: 1606 | C6: 0 | D6: 3656 | E6: 172 | F6: 692 | G6: 6126
A7: Fashion | B7: 26 | C7: 221 | D7: 231 | E7: 418 | F7: 480 | G7: 1376
A8: Home | B8: 1378 | C8: 630 | D8: 0 | E8: 430 | F8: 1765 | G8: 4203
A9: Toys | B9: 0 | C9: 928 | D9: 124 | E9: 43 | F9: 729 | G9: 1824
A10: Grand Total | B10: 3010 | C10: 1842 | D10: 4075 | E10: 1063 | F10: 3666 | G10: 13656

Sheet PIVOT B
B1: Column Labels
B2: Fast | C2: nan | D2: Slow | E2: Grand Total
A3: Count of Order ID | B3: 11 | C3: 66 | D3: 23 | E3: 100

Sheet PIVOT C
A1: Category | B1: (All)
A2: Payment Method | B2: (All)
B4: Column Labels
B5: Central | C5: East | D5: North | E5: South | F5: West | G5: Grand Total
A6: Average of Delivery Time (Days) | B6: 4.2 | C6: 4.25 | D6: 3.625 | E6: 3.3333333 | F6: 3.4285714 | G6: 3.7647059

Sheet KPI_Pivots
A1: Sum of Effective Sales
A2: 13656 | F2: A. | G2: Pivot for total revenue
A23: Delivery Status | B23: (All) | F23: B. | G23: Pivot for Delivery Performance
B25: Column Labels
B26: Fast | C26: nan | D26: Slow | E26: Grand Total
A27: Count of Order ID | B27: 11 | C27: 66 | D27: 23 | E27: 100
F49: C. | G49: Pivot for Region sales
B50: Column Labels
B51: North | C51: West | D51: Central | E51: East | F51: South | G51: Grand Total
A52: Sum of Effective Sales | B52: 4075 | C52: 3666 | D52: 3010 | E52: 1842 | F52: 1063 | G52: 13656
F70: D. | G70: Pivot for Product sales
B71: Column Labels
B72: Smartphone | C72: Cookware Set Pro | D72: Doll House | E72: Headphones | F72: Cookware Set | G72: Shoes | H72: Gaming Mouse | I72: Wall Clock | J72: T-Shirt | K72: Backpack | L72: Leg Set | M72: Formal Shirt | N72: Action Figure | O72: Novel | P72: Puzzle | Q72: Bluetooth Speaker | R72: Jeans | S72: Vacuum Cleaner | T72: Magazine | U72: Smartwatch | V72: Textbook | W72: Lamp | X72: Grand Total
A73: Sum of Effective Sales | B73: 4866 | C73: 3220 | D73: 1239 | E73: 864 | F73: 695 | G73: 577 | H73: 292 | I73: 288 | J73: 269 | K73: 256 | L73: 254 | M73: 215 | N73: 207 | O73: 127 | P73: 124 | Q73: 104 | R73: 59 | S73: 0 | T73: 0 | U73: 0 | V73: 0 | W73: 0 | X73: 13656

Sheet GETPIVOTDATA
B2: A | C2: Total revenue | D2: =GETPIVOTDATA("Effective Sales",KPI_Pivots!$A$1) -> 13656
B4: B | C4: % Fast deleveries | D4: =GETPIVOTDATA("Order ID",KPI_Pivots!$A$25,"Delivery Performance","Fast")/GETPIVOTDATA("Order ID",KPI_Pivots!$A$25) -> 0.11
B7: C | C7: Top 3 regions | D7: Region | E7: Revenue
C8: Top region 1 | D8: =KPI_Pivots!B51 -> North | E8: =GETPIVOTDATA("Effective Sales",KPI_Pivots!$A$50,"Region","North") -> 4075
C9: Top region 2 | D9: =KPI_Pivots!C51 -> West | E9: =GETPIVOTDATA("Effective Sales",KPI_Pivots!$A$50,"Region","West") -> 3666
C10: Top region 3 | D10: =KPI_Pivots!D51 -> Central | E10: =GETPIVOTDATA("Effective Sales",KPI_Pivots!$A$50,"Region","Central") -> 3010
B12: D | C12: Highest-selling Product | D12: =KPI_Pivots!B72 -> Smartphone
C13: sales value | D13: =GETPIVOTDATA("Effective Sales",KPI_Pivots!$A$71,"Product Name","Smartphone") -> 4866
C22: Total revenue | H22: % Fast deleveries
H38: Highest-selling Product
C41: Top 3 regions

Sheet SalesTbl
A1: Order ID | B1: Order Date | C1: Delivery Date | D1: Cancel Date | E1: Customer ID | F1: Product ID | G1: Region | H1: Sale Price/Unit | I1: Quantity | J1: Total Amount | K1: Payment Method | L1: Delivery Status | M1: Fulfillment Partner | N1: Calc Amount | O1: Amount Match Flag | P1: Is Cancelled | Q1: Delivery Time (Days) | R1: Delivery Performance | S1: Effective Sales | T1: Product Name | U1: Category | V1: Customer Name
A2: ORD0001 | B2: 45291 | D2: 45293 | E2: CUST021 | F2: PROD012 | G2: North | H2: 44 | I2: 1 | J2: 44 | K2: Apple Pay | L2: Cancelled | M2: DHL | N2: 44 | O2: OK | P2: 1 | R2: nan | S2: 0 | T2: Lamp | U2: Home | V2: =IFERROR(_xlfn.XLOOKUP(SalesTbl[[#This Row],[Customer ID]], CustomerTbl[Customer ID], CustomerTbl[Customer Name]), "Not Found") -> Zoe Mitchell
A3: ORD0002 | B3: 44979 | C3: 44981 | E3: CUST029 | F3: PROD018 | G3: East | H3: 96 | I3: 4 | J3: 384 | K3: Credit Card | L3: Delivered | M3: DHL | N3: 384 | O3: OK | P3: 0 | Q3: 2 | R3: Fast | S3: 384 | T3: Doll House | U3: Toys | V3: =IFERROR(_xlfn.XLOOKUP(SalesTbl[[#This Row],[Customer ID]], CustomerTbl[Customer ID], CustomerTbl[Customer Name]), "Not Found") -> Ava White
A4: ORD0003 | B4: 45210 | E4: CUST021 | F4: PROD013 | G4: South | H4: 194 | I4: 4 | J4: 776 | K4: Credit Card | L4: In Transit | M4: USPS | N4: 776 | O4: OK | P4: 0 | R4: nan | S4: 0 | T4: Vacuum Cleaner | U4: Home | V4: =IFERROR(_xlfn.XLOOKUP(SalesTbl[[#This Row],[Customer ID]], CustomerTbl[Customer ID], CustomerTbl[Customer Name]), "Not Found") -> Zoe Mitchell
A5: ORD0004 | B5: 45051 | D5: 45057 | E5: CUST044 | F5: PROD013 | G5: North | H5: 196 | I5: 3 | J5: 588 | K5: Paypal | L5: Cancelled | M5: UPS | N5: 588 | O5: OK | P5: 1 | R5: nan | S5: 0 | T5: Vacuum Cleaner | U5: Home | V5: =IFERROR(_xlfn.XLOOKUP(SalesTbl[[#This Row],[Customer ID]], CustomerTbl[Customer ID], CustomerTbl[Customer Name]), "Not Found") -> Grace Ward
A6: ORD0005 | B6: 44959 | C6: 44962 | E6: CUST027 | F6: PROD010 | G6: North | H6: 59 | I6: 1 | J6: 59 | K6: Paypal | L6: Delivered | M6: Amazon Logistics | N6: 59 | O6: OK | P6: 0 | Q6: 3 | R6: Slow | S6: 59 | T6: Jeans | U6: Fashion | V6: =IFERROR(_xlfn.XLOOKUP(SalesTbl[[#This Row],[Customer ID]], CustomerTbl[Customer ID], CustomerTbl[Customer Name]), "Not Found") -> Hazel Brooks
A7: ORD0006 | B7: 45231 | D7: 45232 | E7: CUST009 | F7: PROD010 | G7: North | H7: 58 | I7: 4 | J7: 232 | K7: Amazon Pay | L7: Cancelled | M7: DHL | N7: 232 | O7: OK | P7: 1 | R7: nan | S7: 0 | T7: Jeans | U7: Fashion | V7: =IFERROR(_xlfn.XLOOKUP(SalesTbl[[#This Row],[Customer ID]], CustomerTbl[Customer ID], CustomerTbl[Customer Name]), "Not Found") -> Jackson Allen
A8: ORD0007 | B8: 45152 | D8: 45156 | E8: CUST042 | F8: PROD020 | G8: Central | H8: 105 | I8: 3 | J8: 315 | K8: Debit Card | L8: Cancelled | M8: DHL | N8: 315 | O8: OK | P8: 1 | R8: nan | S8: 0 | T8: Bluetooth Speaker | U8: Electronics | V8: =IFERROR(_xlfn.XLOOKUP(SalesTbl[[#This Row],[Customer ID]], CustomerTbl[Customer ID], CustomerTbl[Customer Name]), "Not Found") -> Noah Wilson
A9: ORD0008 | B9: 45017 | D9: 45022 | E9: CUST019 | F9: PROD021 | G9: West | H9: 37 | I9: 5 | J9: 185 | K9: Paypal | L9: Cancelled | M9: DHL | N9: 185 | O9: OK | P9: 1 | R9: nan | S9: 0 | T9: Wall Clock | U9: Home | V9: =IFERROR(_xlfn.XLOOKUP(SalesTbl[[#This Row],[Customer ID]], CustomerTbl[Customer ID], CustomerTbl[Customer Name]), "Not Found") -> Ava Robinson
A10: ORD0009 | B10: 45128 | E10: CUST013 | F10: PROD019 | G10: Central | H10: 44 | I10: 2 | J10: 88 | K10: Credit Card | L10: In Transit | M10: Amazon Logistics | N10: 88 | O10: OK | P10: 0 | R10: nan | S10: 0 | T10: Formal Shirt | U10: Fashion | V10: =IFERROR(_xlfn.XLOOKUP(SalesTbl[[#This Row],[Customer ID]], CustomerTbl[Customer ID], CustomerTbl[Customer Name]), "Not Found") -> Olivia Martinez
A11: ORD0010 | B11: 45289 | E11: CUST019 | F11: PROD003 | G11: South | H11: 141 | I11: 4 | J11: 564 | K11: Debit Card | L11: In Transit | M11: DHL | N11: 564 | O11: OK | P11: 0 | R11: nan | S11: 0 | T11: Cookware Set | U11: Home | V11: =IFERROR(_xlfn.XLOOKUP(SalesTbl[[#This Row],[Customer ID]], CustomerTbl[Customer ID], CustomerTbl[Customer Name]), "Not Found") -> Ava Robinson
A12: ORD0011 | B12: 45050 | D12: 45054 | E12: CUST046 | F12: PROD014 | G12: South | H12: 249 | I12: 1 | J12: 249 | K12: Amazon Pay | L12: Cancelled | M12: USPS | N12: 249 | O12: OK | P12: 1 | R12: nan | S12: 0 | T12: Smartwatch | U12: Electronics | V12: =IFERROR(_xlfn.XLOOKUP(SalesTbl[[#This Row],[Customer ID]], CustomerTbl[Customer ID], CustomerTbl[Customer Name]), "Not Found") -> Emily Johnson
A13: ORD0012 | B13: 45132 | E13: CUST045 | F13: PROD014 | G13: Central | H13: 247 | I13: 3 | J13: 741 | K13: Amazon Pay | L13: In Transit | M13: FedEx | N13: 741 | O13: OK | P13: 0 | R13: nan | S13: 0 | T13: Smartwatch | U13: Electronics | V13: =IFERROR(_xlfn.XLOOKUP(SalesTbl[[#This Row],[Customer ID]], CustomerTbl[Customer ID], CustomerTbl[Customer Name]), "Not Found") -> Emily Johnson
A14: ORD0013 | B14: 44982 | D14: 44985 | E14: CUST023 | F14: PROD006 | G14: Central | H14: 96 | I14: 1 | J14: 96 | K14: Apple Pay | L14: Cancelled | M14: Amazon Logistics | N14: 96 | O14: OK | P14: 1 | R14: nan | S14: 0 | T14: Shoes | U14: Fashion | V14: =IFERROR(_xlfn.XLOOKUP(SalesTbl[[#This Row],[Customer ID]], CustomerTbl[Customer ID], CustomerTbl[Customer Name]), "Not Found") -> Charlotte Reed
A15: ORD0014 | B15: 44981 | D15: 44982 | E15: CUST033 | F15: PROD017 | G15: West | H15: 74 | I15: 5 | J15: 370 | K15: Apple Pay | L15: Cancelled | M15: Amazon Logistics | N15: 370 | O15: OK | P15: 1 | R15: nan | S15: 0 | T15: Gaming Mouse | U15: Electronics | V15: =IFERROR(_xlfn.XLOOKUP(SalesTbl[[#This Row],[Customer ID]], CustomerTbl[Customer ID], CustomerTbl[Customer Name]), "Not Found") -> Hazel Rivera
A16: ORD0015 | B16: 45164 | D16: 45171 | E16: CUST033 | F16: PROD005 | G16: South | H16: 27 | I16: 1 | J16: 27 | K16: Credit Card | L16: Cancelled | M16: Amazon Logistics | N16: 27 | O16: OK | P16: 1 | R16: nan | S16: 0 | T16: T-Shirt | U16: Fashion | V16: =IFERROR(_xlfn.XLOOKUP(SalesTbl[[#This Row],[Customer ID]], CustomerTbl[Customer ID], CustomerTbl[Customer Name]), "Not Found") -> Hazel Rivera
A17: ORD0016 | B17: 44970 | E17: CUST047 | F17: PROD005 | G17: South | H17: 27 | I17: 3 | J17: 81 | K17: Debit Card | L17: In Transit | M17: Amazon Logistics | N17: 81 | O17: OK | P17: 0 | R17: nan | S17: 0 | T17: T-Shirt | U17: Fashion | V17: =IFERROR(_xlfn.XLOOKUP(SalesTbl[[#This Row],[Customer ID]], CustomerTbl[Customer ID], CustomerTbl[Customer Name]), "Not Found") -> Scarlett Murphy
A18: ORD0017 | B18: 45105 | C18: 45108 | E18: CUST045 | F18: PROD015 | G18: East | H18: 21 | I18: 3 | J18: 63 | K18: Credit Card | L18: Delivered | M18: DHL | N18: 63 | O18: OK | P18: 0 | Q18: 3 | R18: Slow | S18: 63 | T18: Novel | U18: Books | V18: =IFERROR(_xlfn.XLOOKUP(SalesTbl[[#This Row],[Customer ID]], CustomerTbl[Customer ID], CustomerTbl[Customer Name]), "Not Found") -> Emily Johnson
A19: ORD0018 | B19: 45258 | E19: CUST011 | F19: PROD008 | G19: West | H19: 70 | I19: 5 | J19: 350 | K19: Paypal | L19: In Transit | M19: Amazon Logistics | N19: 350 | O19: OK | P19: 0 | R19: nan | S19: 0 | T19: Textbook | U19: Books | V19: =IFERROR(_xlfn.XLOOKUP(SalesTbl[[#This Row],[Customer ID]], CustomerTbl[Customer ID], CustomerTbl[Customer Name]), "Not Found") -> Mason Hall
A20: ORD0019 | B20: 45163 | E20: CUST041 | F20: PROD006 | G20: South | H20: 94 | I20: 4 | J20: 376 | K20: Credit Card | L20: In Transit | M20: USPS | N20: 376 | O20: OK | P20: 0 | R20: nan | S20: 0 | T20: Shoes | U20: Fashion | V20: =IFERROR(_xlfn.XLOOKUP(SalesTbl[[#This Row],[Customer ID]], CustomerTbl[Customer ID], CustomerTbl[Customer Name]), "Not Found") -> Jacob Price
A21: ORD0020 | B21: 45028 | E21: CUST025 | F21: PROD001 | G21: North | H21: 813 | I21: 2 | J21: 1626 | K21: Credit Card | L21: In Transit | M21: FedEx | N21: 1626 | O21: OK | P21: 0 | R21: nan | S21: 0 | T21: Smartphone | U21: Electronics | V21: =IFERROR(_xlfn.XLOOKUP(SalesTbl[[#This Row],[Customer ID]], CustomerTbl[Customer ID], CustomerTbl[Customer Name]), "Not Found") -> Emma King
A22: ORD0021 | B22: 45201 | E22: CUST013 | F22: PROD015 | G22: Central | H22: 21 | I22: 4 | J22: 84 | K22: Paypal | L22: In Transit | M22: Amazon Logistics | N22: 84 | O22: OK | P22: 0 | R22: nan | S22: 0 | T22: Novel | U22: Books | V22: =IFERROR(_xlfn.XLOOKUP(SalesTbl[[#This Row],[Customer ID]], CustomerTbl[Customer ID], CustomerTbl[Customer Name]), "Not Found") -> Olivia Martinez
A23: ORD0022 | B23: 45239 | E23: CUST023 | F23: PROD012 | G23: West | H23: 46 | I23: 5 | J23: 230 | K23: Paypal | L23: In Transit | M23: USPS | N23: 230 | O23: OK | P23: 0 | R23: nan | S23: 0 | T23: Lamp | U23: Home | V23: =IFERROR(_xlfn.XLOOKUP(SalesTbl[[#This Row],[Customer ID]], CustomerTbl[Customer ID], CustomerTbl[Customer Name]), "Not Found") -> Charlotte Reed
A24: ORD0023 | B24: 44970 | D24: 44971 | E24: CUST016 | F24: PROD010 | G24: West | H24: 58 | I24: 3 | J24: 174 | K24: Amazon Pay | L24: Cancelled | M24: Amazon Logistics | N24: 174 | O24: OK | P24: 1 | R24: nan | S24: 0 | T24: Jeans | U24: Fashion | V24: =IFERROR(_xlfn.XLOOKUP(SalesTbl[[#This Row],[Customer ID]], CustomerTbl[Customer ID], CustomerTbl[Customer Name]), "Not Found") -> Elijah Lewis
A25: ORD0024 | B25: 45232 | C25: 45235 | E25: CUST028 | F25: PROD006 | G25: West | H25: 96 | I25: 5 | J25: 480 | K25: Amazon Pay | L25: Delivered | M25: Amazon Logistics | N25: 480 | O25: OK | P25: 0 | Q25: 3 | R25: Slow | S25: 480 | T25: Shoes | U25: Fashion | V25: =IFERROR(_xlfn.XLOOKUP(SalesTbl[[#This Row],[Customer ID]], CustomerTbl[Customer ID], CustomerTbl[Customer Name]), "Not Found") -> Lily Bennett
A26: ORD0025 | B26: 45074 | C26: 45076 | E26: CUST040 | F26: PROD002 | G26: South | H26: 43 | I26: 1 | J26: 43 | K26: Debit Card | L26: Delivered | M26: Amazon Logistics | N26: 43 | O26: OK | P26: 0 | Q26: 2 | R26: Fast | S26: 43 | T26: Action Figure | U26: Toys | V26: =IFERROR(_xlfn.XLOOKUP(SalesTbl[[#This Row],[Customer ID]], CustomerTbl[Customer ID], CustomerTbl[Customer Name]), "Not Found") -> Benjamin Clark
A27: ORD0026 | B27: 45214 | C27: 45220 | E27: CUST027 | F27: PROD022 | G27: South | H27: 64 | I27: 4 | J27: 256 | K27: Debit Card | L27: Delivered | M27: USPS | N27: 256 | O27: OK | P27: 0 | Q27: 6 | R27: Slow | S27: 256 | T27: Backpack | U27: Fashion | V27: =IFERROR(_xlfn.XLOOKUP(SalesTbl[[#This Row],[Customer ID]], CustomerTbl[Customer ID], CustomerTbl[Customer Name]), "Not Found") -> Hazel Brooks
A28: ORD0027 | B28: 44942 | E28: CUST018 | F28: PROD008 | G28: South | H28: 70 | I28: 2 | J28: 140 | K28: Amazon Pay | L28: In Transit | M28: Amazon Logistics | N28: 140 | O28: OK | P28: 0 | R28: nan | S28: 0 | T28: Textbook | U28: Books | V28: =IFERROR(_xlfn.XLOOKUP(SalesTbl[[#This Row],[Customer ID]], CustomerTbl[Customer ID], CustomerTbl[Customer Name]), "Not Found") -> Grace Scott
A29: ORD0028 | B29: 45208 | E29: CUST018 | F29: PROD018 | G29: Central | H29: 97 | I29: 3 | J29: 291 | K29: Credit Card | L29: In Transit | M29: Amazon Logistics | N29: 291 | O29: OK | P29: 0 | R29: nan | S29: 0 | T29: Doll House | U29: Toys | V29: =IFERROR(_xlfn.XLOOKUP(SalesTbl[[#This Row],[Customer ID]], CustomerTbl[Customer ID], CustomerTbl[Customer Name]), "Not Found") -> Grace Scott
A30: ORD0029 | B30: 45206 | D30: 45209 | E30: CUST007 | F30: PROD021 | G30: East | H30: 37 | I30: 3 | J30: 111 | K30: Apple Pay | L30: Cancelled | M30: DHL | N30: 111 | O30: OK | P30: 1 | R30: nan | S30: 0 | T30: Wall Clock | U30: Home | V30: =IFERROR(_xlfn.XLOOKUP(SalesTbl[[#This Row],[Customer ID]], CustomerTbl[Customer ID], CustomerTbl[Customer Name]), "Not Found") -> Liam Walker
A31: ORD0030 | B31: 44971 | E31: CUST008 | F31: PROD008 | G31: North | H31: 69 | I31: 5 | J31: 345 | K31: Amazon Pay | L31: In Transit | M31: Amazon Logistics | N31: 345 | O31: OK | P31: 0 | R31: nan | S31: 0 | T31: Textbook | U31: Books | V31: =IFERROR(_xlfn.XLOOKUP(SalesTbl[[#This Row],[Customer ID]], CustomerTbl[Customer ID], CustomerTbl[Customer Name]), "Not Found") -> Harper Young
A32: ORD0031 | B32: 45011 | E32: CUST014 | F32: PROD002 | G32: North | H32: 42 | I32: 5 | J32: 210 | K32: Amazon Pay | L32: In Transit | M32: UPS | N32: 210 | O32: OK | P32: 0 | R32: nan | S32: 0 | T32: Action Figure | U32: Toys | V32: =IFERROR(_xlfn.XLOOKUP(SalesTbl[[#This Row],[Customer ID]], CustomerTbl[Customer ID], CustomerTbl[Customer Name]), "Not Found") -> Harper Young
A33: ORD0032 | B33: 45092 | D33: 45099 | E33: CUST037 | F33: PROD009 | G33: East | H33: 11 | I33: 5 | J33: 55 | K33: Debit Card | L33: Cancelled | M33: FedEx | N33: 55 | O33: OK | P33: 1 | R33: nan | S33: 0 | T33: Magazine | U33: Books | V33: =IFERROR(_xlfn.XLOOKUP(SalesTbl[[#This Row],[Customer ID]], CustomerTbl[Customer ID], CustomerTbl[Customer Name]), "Not Found") -> Emily Johnson
A34: ORD0033 | B34: 45068 | C34: 45069 | E34: CUST016 | F34: PROD005 | G34: South | H34: 27 | I34: 2 | J34: 54 | K34: Apple Pay | L34: Delivered | M34: USPS | N34: 54 | O34: OK | P34: 0 | Q34: 1 | R34: Fast | S34: 54 | T34: T-Shirt | U34: Fashion | V34: =IFERROR(_xlfn.XLOOKUP(SalesTbl[[#This Row],[Customer ID]], CustomerTbl[Customer ID], CustomerTbl[Customer Name]), "Not Found") -> Elijah Lewis
A35: ORD0034 | B35: 45250 | E35: CUST025 | F35: PROD015 | G35: South | H35: 21 | I35: 1 | J35: 21 | K35: Amazon Pay | L35: In Transit | M35: DHL | N35: 21 | O35: OK | P35: 0 | R35: nan | S35: 0 | T35: Novel | U35: Books | V35: =IFERROR(_xlfn.XLOOKUP(SalesTbl[[#This Row],[Customer ID]], CustomerTbl[Customer ID], CustomerTbl[Customer Name]), "Not Found") -> Emma King
A36: ORD0035 | B36: 45282 | C36: 45286 | E36: CUST032 | F36: PROD011 | G36: South | H36: 172 | I36: 1 | J36: 172 | K36: Paypal | L36: Delivered | M36: USPS | N36: 172 | O36: OK | P36: 0 | Q36: 4 | R36: Slow | S36: 172 | T36: Headphones | U36: Electronics | V36: =IFERROR(_xlfn.XLOOKUP(SalesTbl[[#This Row],[Customer ID]], CustomerTbl[Customer ID], CustomerTbl[Customer Name]), "Not Found") -> Luke Gray
A37: ORD0036 | B37: 45130 | E37: CUST014 | F37: PROD016 | G37: North | H37: 212 | I37: 3 | J37: 636 | K37: Amazon Pay | L37: In Transit | M37: UPS | N37: 636 | O37: OK | P37: 0 | R37: nan | S37: 0 | T37: Cookware Set Pro | U37: Home | V37: =IFERROR(_xlfn.XLOOKUP(SalesTbl[[#This Row],[Customer ID]], CustomerTbl[Customer ID], CustomerTbl[Customer Name]), "Not Found") -> Harper Young
A38: ORD0037 | B38: 45216 | C38: 45221 | E38: CUST044 | F38: PROD002 | G38: East | H38: 41 | I38: 4 | J38: 164 | K38: Credit Card | L38: Delivered | M38: Amazon Logistics | N38: 164 | O38: OK | P38: 0 | Q38: 5 | R38: Slow | S38: 164 | T38: Action Figure | U38: Toys | V38: =IFERROR(_xlfn.XLOOKUP(SalesTbl[[#This Row],[Customer ID]], CustomerTbl[Customer ID], CustomerTbl[Customer Name]), "Not Found") -> Grace Ward
A39: ORD0038 | B39: 45160 | D39: 45162 | E39: CUST028 | F39: PROD007 | G39: North | H39: 32 | I39: 2 | J39: 64 | K39: Debit Card | L39: Cancelled | M39: FedEx | N39: 64 | O39: OK | P39: 1 | R39: nan | S39: 0 | T39: Puzzle | U39: Toys | V39: =IFERROR(_xlfn.XLOOKUP(SalesTbl[[#This Row],[Customer ID]], CustomerTbl[Customer ID], CustomerTbl[Customer Name]), "Not Found") -> Lily Bennett
A40: ORD0039 | B40: 45262 | E40: CUST024 | F40: PROD022 | G40: East | H40: 66 | I40: 2 | J40: 132 | K40: Apple Pay | L40: In Transit | M40: DHL | N40: 132 | O40: OK | P40: 0 | R40: nan | S40: 0 | T40: Backpack | U40: Fashion | V40: =IFERROR(_xlfn.XLOOKUP(SalesTbl[[#This Row],[Customer ID]], CustomerTbl[Customer ID], CustomerTbl[Customer Name]), "Not Found") -> Scarlett Murphy
...

Sheet ProductTbl
A1: Product ID | B1: Product Name | C1: Category | D1: Cost Price | E1: Description
A2: PROD001 | B2: Smartphone | C2: Electronics | D2: 749 | E2: Latest model with 5G, dual SIM, and OLED display
A3: PROD002 | B3: Action Figure | C3: Toys | D3: 39 | E3: Collectible superhero action figure for ages 8+
A4: PROD003 | B4: Cookware Set | C4: Home | D4: 129 | E4: Non-stick 5-piece cookware set for daily use
A5: PROD004 | B5: Leg Set | C5: Toys | D5: 59 | E5: 300-piece creative building block toy set
A6: PROD005 | B6: T-Shirt | C6: Fashion | D6: 25 | E6: Cotton t-shirt, available in multiple colors
A7: PROD006 | B7: Shoes | C7: Fashion | D7: 89 | E7: Casual wear shoes for men and women
A8: PROD007 | B8: Puzzle | C8: Toys | D8: 29 | E8: 1000-piece jigsaw puzzle
A9: PROD008 | B9: Textbook | C9: Books | D9: 65 | E9: University-level textbook on computer science
A10: PROD009 | B10: Magazine | C10: Books | D10: 10 | E10: Monthly lifestyle magazine
A11: PROD010 | B11: Jeans | C11: Fashion | D11: 55 | E11: Slim fit denim jeans with stretch
A12: PROD011 | B12: Headphones | C12: Electronics | D12: 159 | E12: Wireless noise-cancelling over-ear headphones
A13: PROD012 | B13: Lamp | C13: Home | D13: 42 | E13: LED desk lamp with dimmable light
... A23: PROD022 | B23: Backpack | C23: Fashion | D23: 60 | E23: Waterproof backpack with laptop compartment

Sheet RegionTbl
A1: Region | B1: Sales Target
A2: Central | B2: 97500
A3: East | B3: 50500
A4: North | B4: 105000
A5: South | B5: 91500
A6: West | B6: 90750

Sheet CustomerTbl
A1: Customer ID | B1: Customer Name | C1: Customer Type | D1: City | E1: State
A2: CUST001 | B2: James Miller | C2: Business | D2: New York | E2: New York
A3: CUST002 | B3: Emily Johnson | C3: Prime | D3: Seattle | E3: Washington
A4: CUST003 | B4: Ethan Davis | C4: Prime | D4: Austin | E4: Texas
A5: CUST004 | B5: Noah Wilson | C5: Prime | D5: San Francisco | E5: California
A6: CUST005 | B6: Olivia Martinez | C6: Prime | D6: Seattle | E6: Washington
A7: CUST006 | B7: Ava Robinson | C7: Prime | D7: Chicago | E7: Illinois
A8: CUST007 | B8: Liam Walker | C8: Prime | D8: San Francisco | E8: California
A9: CUST008 | B9: Harper Young | C9: Business | D9: Dallas | E9: Texas
A10: CUST009 | B10: Jackson Allen | C10: Business | D10: Seattle | E10: Washington
A11: CUST010 | B11: Charlotte Harris | C11: Prime | D11: Chicago | E11: Illinois
A12: CUST011 | B12: Mason Hall | C12: Business | D12: Miami | E12: Florida
... A50: CUST049 | B50: Hazel Gray | C50: Business | D50: Chicago | E50: Illinois

Sheet Pivot_Ref_SalesByRegCat
A1: Region | B1: Books | C1: Electronics | D1: Fashion | E1: Home | F1: Toys
A2: Central | B2: 0 | C2: 1606 | D2: 26 | E2: 1378 | F2: 0
A3: East | B3: 63 | C3: 0 | D3: 221 | E3: 630 | F3: 928
A4: North | B4: 64 | C4: 3656 | D4: 231 | E4: 0 | F4: 124
A5: South | B5: 0 | C5: 172 | D5: 418 | E5: 430 | F5: 43
A6: West | B6: 0 | C6: 692 | D6: 480 | E6: 1765 | F6: 729

Sheet Pivot_Ref_CountByStatus
A1: Delivery Status | B1: Orders
A2: Cancelled | B2: 30
A3: Delivered | B3: 34
A4: In Transit | B4: 36

Sheet Pivot_Ref_AvgDelTime
A1: Average_Delivery_Time_Days
A2: 3.7647059

Sheet Pivot_Ref_RegionKPI
A1: Region | B1: Total_Orders | C1: Cancelled_Orders | D1: Effective_Sales | E1: Cancellation_Rate_%
A2: Central | B2: 14 | C2: 5 | D2: 3010 | E2: 35.714286
A3: East | B3: 18 | C3: 3 | D3: 1842 | E3: 16.666667
A4: North | B4: 25 | C4: 10 | D4: 4075 | E4: 40
A5: South | B5: 20 | C5: 4 | D5: 1063 | E5: 20
A6: West | B6: 23 | C6: 8 | D6: 3666 | E6: 34.782609

Sheet Pivot_Ref_ProductSales
A1: Product ID | B1: Product Name | C1: Effective_Sales
A2: PROD001 | B2: Smartphone | C2: 4866
A3: PROD016 | B3: Cookware Set Pro | C3: 3220
A4: PROD018 | B4: Doll House | C4: 1239
A5: PROD011 | B5: Headphones | C5: 864
A6: PROD003 | B6: Cookware Set | C6: 695
A7: PROD006 | B7: Shoes | C7: 577
A8: PROD017 | B8: Gaming Mouse | C8: 292
A9: PROD021 | B9: Wall Clock | C9: 288
A10: PROD005 | B10: T-Shirt | C10: 269
A11: PROD022 | B11: Backpack | C11: 256
A12: PROD004 | B12: Leg Set | C12: 254
A13: PROD019 | B13: Formal Shirt | C13: 215
... A23: PROD012 | B23: Lamp | C23: 0

Sheet Brainstorm answers
C2: Brainstorming Reflection
C4: ● What is the most successful product category in terms of revenue?
C5: Ans: Smatphone is the most successful product category in terms of revenue.
C7: ● Which region has the highest order cancellation rate?
C8: Ans: NORTH region has the highest cancellation rate of 40%.
C10: ● How many orders were delivered within 2 days?
C11: Ans: 11 orders were deleivered within 2 days.
C13: ● How has the use of XLOOKUP simplified cross-sheet analysis?
C14: Ans: Replaces old lookup methods (VLOOKUP, HLOOKUP, INDEX+MATCH)
C16: we had to use VLOOKUP with column numbers (get errors if columns are shifted) or combine INDEX and MATCH (harder for beginners).
C17: With XLOOKUP, we directly specify lookup column and return column — no need to count positions.
C19: Example:
... C24: Ans: The analysis of delivery performance revealed that not all regions consistently achieve the “Fast Delivery” benchmark of 2 days. To improve this, the company should strengthen logistics partnerships in underperforming regions, optimize warehouse placement, and introduce priority shipping options. Automating order processing can further cut handling times, while tracking product categories with frequent delays (such as bulky goods) can help design specialized workflows. Additionally, timely customer communication during delays will improve satisfaction and reduce cancellations. Overall, focusing on operational efficiency and proactive service will significantly enhance delivery performance.

Sheet README
A1: Instructions
A2: HOW TO USE THIS TEMPLATE
A3: 1) 'CleanedData' has helper columns: Delivery Time (Days), Delivery Performance, Effective Sales, Is Cancelled.
A4: 2) Insert > PivotTable from 'CleanedData' (use entire table). Recommended pivots:
A5: a) Rows: Region; Columns: Category; Values: Sum of Effective Sales.
A6: b) Rows: Delivery Status; Values: Count of Order ID.
A7: c) Rows: Region; Values: Average of Delivery Time (Days).
A8: Filters/Slicers: Region, Payment Method, Delivery Status; Group Order Date by Months.
A9: 3) XLOOKUP customer names in a new column on 'CleanedData':
A10: =IFERROR(XLOOKUP([@[Customer ID]],CustomerMaster!A:B,CustomerMaster!B:B),"Not Found")
A11: 4) Cancellation Rate by Region = Cancelled Orders / Total Orders (see Pivot_Ref_RegionKPI or create in pivot).
A12: 5) KPI Cards: Total Revenue (sum Effective Sales), % Fast Deliveries, Top 3 Regions, Highest-Selling Product.
A13: 6) Use PivotCharts for visuals; place slicers left, charts center, KPI cards right.
